
<?xml version="1.0"?>

<robot name="robotiq_85_gripper">
  <!-- control -->
  <link name="base_link">
    <inertial>
      <mass value="0" />
      <inertia ixx = "0" ixy = "0" ixz = "0"
               iyx = "0" iyy = "0" iyz = "0"
               izx = "0" izy = "0" izz = "0" />
    </inertial>
  </link>

  <joint name="center_x" type="prismatic">
    <parent link="base_link"/>
    <child link="y_control"/>
    <axis xyz="1 0 0"/>
    <limit effort="1000.0" lower="-10" upper="10" velocity="0.2"/>
  </joint>

  <link name="y_control">
    <inertial>
      <mass value="0.1" />
      <inertia ixx = "0" ixy = "0" ixz = "0"
               iyx = "0" iyy = "0" iyz = "0"
               izx = "0" izy = "0" izz = "0" />
    </inertial>
  </link>

  <joint name="center_y" type="prismatic">
    <parent link="y_control"/>
    <child link="z_control"/>
    <axis xyz="0 1 0"/>
    <limit effort="1000.0" lower="-10" upper="10" velocity="0.2"/>
  </joint>

  <link name="z_control">
    <inertial>
      <mass value="0.1" />
      <inertia ixx = "0" ixy = "0" ixz = "0"
               iyx = "0" iyy = "0" iyz = "0"
               izx = "0" izy = "0" izz = "0" />
    </inertial>
  </link>

  <joint name="center_z" type="prismatic">
    <parent link="z_control"/>
    <child link="yaw_control"/>
    <axis xyz="0 0 1"/>
    <limit effort="1000.0" lower="-10" upper="10" velocity="0.2"/>
  </joint>

  <link name="yaw_control">
    <inertial>
      <mass value="0.01" />
      <inertia ixx = "0" ixy = "0" ixz = "0"
               iyx = "0" iyy = "0" iyz = "0"
               izx = "0" izy = "0" izz = "0" />
    </inertial>
  </link>

  <joint name="gripper_yaw" type="revolute">
    <parent link="yaw_control"/>
    <child link="pitch_control"/>
    <axis xyz="0 0 1"/>
    <limit lower="-31.4" upper="31.4" velocity="3.14" effort="10000"/>

  </joint>

  <link name="pitch_control">
    <inertial>
      <mass value="0.1" />
      <inertia ixx = "0" ixy = "0" ixz = "0"
               iyx = "0" iyy = "0" iyz = "0"
               izx = "0" izy = "0" izz = "0" />
    </inertial>
  </link>

  <joint name="gripper_pitch" type="revolute">
    <parent link="pitch_control"/>
    <child link="roll_control"/>
    <axis xyz="0 1 0"/>
    <limit lower="-31.4" upper="31.4" velocity="3.14" effort="10000"/>

  </joint>

  <link name="roll_control">
    <inertial>
      <mass value="0.1" />
      <inertia ixx = "0" ixy = "0" ixz = "0"
               iyx = "0" iyy = "0" iyz = "0"
               izx = "0" izy = "0" izz = "0" />
    </inertial>
  </link>

  <joint name="gripper_roll" type="revolute">
    <parent link="roll_control"/>
    <child link="dummy_center_indicator_link"/>
    <axis xyz="1 0 0"/>
    <limit lower="-31.4" upper="31.4" velocity="3.14" effort="100000"/>
  </joint>

  <link name="dummy_center_indicator_link">
    <visual>
      <geometry>
        <box size="0.020 0.085 0.002"/>
      </geometry>
    </visual>
    <inertial>
      <mass value="0.1" />
      <inertia ixx = "0" ixy = "0" ixz = "0"
               iyx = "0" iyy = "0" iyz = "0"
               izx = "0" izy = "0" izz = "0" />
    </inertial>
  </link>

  <joint name="dummy_center_fixed_joint" type="fixed">
    <parent link="dummy_center_indicator_link"/>
    <child link="panda_hand"/>
    <origin xyz=" -0.087 0 0" rpy="0 1.57 0" />
  </joint>


  <link name="panda_hand">
  	<inertial>
      <origin rpy="0 0 0" xyz="0 0 0.04"/>
       <mass value=".81"/>
       <inertia ixx="0.1" ixy="0" ixz="0" iyy="0.1" iyz="0" izz="0.1"/>
    </inertial>
    <visual>
      <geometry>
        <mesh filename="package://meshes/visual/hand.obj"/>
      </geometry>
      <material name="panda_white"/>
    </visual>
    <collision>
      <geometry>
        <mesh filename="package://meshes/collision/hand.obj"/>
      </geometry>
      <material name="panda_white"/>
    </collision>
  </link>
  <link name="panda_leftfinger">
       <contact>
      <friction_anchor/>
      <stiffness value="30000.0"/>
      <damping value="1000.0"/>
      <spinning_friction value="0.1"/>
      <lateral_friction value="1.0"/>
    </contact>
  	<inertial>
      <origin rpy="0 0 0" xyz="0 0.01 0.02"/>
       <mass value="0.1"/>
       <inertia ixx="0.1" ixy="0" ixz="0" iyy="0.1" iyz="0" izz="0.1"/>
    </inertial>
    <visual>
      <geometry>
        <mesh filename="package://meshes/visual/finger.obj"/>
      </geometry>
      <material name="panda_white"/>
    </visual>
    <collision>
      <geometry>
        <mesh filename="package://meshes/collision/finger.obj"/>
      </geometry>
      <material name="panda_white"/>
    </collision>
  </link>
  <link name="panda_rightfinger">
        <contact>
      <friction_anchor/>
      <stiffness value="30000.0"/>
      <damping value="1000.0"/>
      <spinning_friction value="0.1"/>
      <lateral_friction value="1.0"/>
    </contact>

  	<inertial>
      <origin rpy="0 0 0" xyz="0 -0.01 0.02"/>
       <mass value="0.1"/>
       <inertia ixx="0.1" ixy="0" ixz="0" iyy="0.1" iyz="0" izz="0.1"/>
    </inertial>
    <visual>
      <origin rpy="0 0 3.14159265359" xyz="0 0 0"/>
      <geometry>
        <mesh filename="package://meshes/visual/finger.obj"/>
      </geometry>
      <material name="panda_white"/>
    </visual>
    <collision>
      <origin rpy="0 0 3.14159265359" xyz="0 0 0"/>
      <geometry>
        <mesh filename="package://meshes/collision/finger.obj"/>
      </geometry>
      <material name="panda_white"/>
    </collision>
  </link>
  <joint name="panda_finger_joint1" type="prismatic">
    <parent link="panda_hand"/>
    <child link="panda_leftfinger"/>
    <origin rpy="0 0 0" xyz="0 0 0.0584"/>
    <axis xyz="0 1 0"/>
    <limit effort="20" lower="0.0" upper="0.08" velocity="0.2"/>
  </joint>
  <joint name="panda_finger_joint2" type="prismatic">
    <parent link="panda_hand"/>
    <child link="panda_rightfinger"/>
    <origin rpy="0 0 0" xyz="0 0 0.0584"/>
    <axis xyz="0 -1 0"/>
    <limit effort="20" lower="0.0" upper="0.08" velocity="0.2"/>
    <mimic joint="panda_finger_joint1"/>
  </joint>
   <link name="panda_grasptarget">
 <inertial>
      <origin rpy="0 0 0" xyz="0 0 0"/>
       <mass value="0.0"/>
       <inertia ixx="0.1" ixy="0" ixz="0" iyy="0.1" iyz="0" izz="0.1"/>
    </inertial>
   </link>
   <joint name="panda_grasptarget_hand" type="fixed">
    <parent link="panda_hand"/>
    <child link="panda_grasptarget"/>
    <origin rpy="0 0 0" xyz="0 0 0.105"/>
  </joint>
  </robot>